Workbook

Sheet Recompiled Data
A1: Site Name | B1: Species name | C1: Precipitation | D1: Date | E1: Time-Hour at which heard | F1: 5 Minute Block | G1: Total Minutes Called | H1: Scientific Name | I1: Different species calling at the same time
A2: Retention Pond | B2: Cope's Gray | C2: 0 | D2: 45813 | E2: 0.54166667 | F2: 1 | H2: Dryophytes chrysoscelis | I2: 2
B3: Summary: | C3: =C2 -> 0 | F3: =F2 -> 1 | G3: =COUNT(F2) -> 1
A4: Retention Pond | B4: Cope's Gray | C4: 0 | D4: 45814 | E4: 0 | F4: 1 | H4: Dryophytes chrysoscelis | I4: 3
C5: 0 | E5: 0.041666667 | F5: 1 | I5: 1
C6: 0 | E6: 0.042361111 | F6: 0 | I6: 1
C7: 0 | E7: 0.043055556 | F7: 0 | I7: 3
C8: 0 | E8: 0.04375 | F8: 0 | I8: 2
C9: 0 | E9: 0.044444444 | F9: 0 | I9: 1
C10: 0 | E10: 0.083333333 | F10: 1 | I10: 1
C11: 0 | E11: 0.125 | F11: 1 | I11: 1
C12: 0 | E12: 0.16805556 | F12: 1 | I12: 1
C13: 0 | E13: 0.16875 | F13: 0 | I13: 2
C14: 0 | E14: 0.16944444 | F14: 0 | I14: 3
C15: 0 | E15: 0.20972222 | F15: 1 | I15: 3
C16: 0 | E16: 0.21041667 | F16: 0 | I16: 3
... C28: 0 | E28: 0.96111111 | F28: 0 | I28: 3
B29: Summary: | C29: =SUM(C4:C28) -> 0 | F29: =SUM(F4:F28) -> 9 | G29: =COUNT(F4:F28) -> 25
A30: Retention Pond | B30: Cope's Gray | C30: 0 | D30: 45815 | E30: 0 | F30: 1 | H30: Dryophytes chrysoscelis | I30: 2
C31: 0 | E31: 0.00069444444 | F31: 0 | I31: 1
C32: 0 | E32: 0.0013888889 | F32: 0 | I32: 3
C33: 0 | E33: 0.0020833333 | F33: 0 | I33: 3
C34: 0 | E34: 0.0027777778 | F34: 0 | I34: 3
C35: 0 | E35: 0.041666667 | F35: 1 | I35: 2
C36: 0 | E36: 0.04375 | F36: 0 | I36: 2
C37: 0 | E37: 0.083333333 | F37: 1 | I37: 2
C38: 0 | E38: 0.084027778 | F38: 0 | I38: 3
C39: 0 | E39: 0.084722222 | F39: 0 | I39: 3
C40: 0 | E40: 0.125 | F40: 1 | I40: 1
B41: Summary: | C41: =SUM(C30:C40) -> 0 | F41: =SUM(F30:F40) -> 4 | G41: =COUNT(F30:F40) -> 11
A42: Retention Pond | B42: Green treefrog | C42: 0 | D42: 45814 | E42: 0 | F42: 1 | H42: Hyla cinerea | I42: 3
C43: 0 | E43: 0.00069444444 | F43: 0 | I43: 3
C44: 0 | E44: 0.0013888889 | F44: 0 | I44: 3
C45: 0 | E45: 0.0020833333 | F45: 0 | I45: 3
C46: 0 | E46: 0.0027777778 | F46: 0 | I46: 3
C47: 0 | E47: 0.043055556 | F47: 1 | I47: 3
C48: 0 | E48: 0.12777778 | F48: 1 | I48: 2
C49: 0 | E49: 0.16875 | F49: 1 | I49: 2
C50: 0 | E50: 0.16944444 | F50: 0 | I50: 3
C51: 0 | E51: 0.20972222 | F51: 1 | I51: 3
...

Sheet Sheet1
A1: site | B1: species | C1: precipitation | D1: date | E1: time_hour_heard | F1: five_min | G1: total_min | H1: scientific_name | I1: total_species
A2: Micropond | B2: Bullfrog | C2: 0 | D2: 45874 | E2: 0 | F2: 0 | G2: 12 | H2: Lithobates catesbeianus | I2: 3
A3: Micropond | B3: Bullfrog | C3: 0 | D3: 45874 | E3: 0.0013888889 | F3: 1 | G3: 12 | H3: Lithobates catesbeianus | I3: 3
A4: Micropond | B4: Bullfrog | C4: 0 | D4: 45874 | E4: 0.041666667 | F4: 1 | G4: 12 | H4: Lithobates catesbeianus | I4: 3
A5: Micropond | B5: Bullfrog | C5: 0 | D5: 45874 | E5: 0.043055556 | F5: 0 | G5: 12 | H5: Lithobates catesbeianus | I5: 3
A6: Micropond | B6: Bullfrog | C6: 0 | D6: 45874 | E6: 0.083333333 | F6: 1 | G6: 12 | H6: Lithobates catesbeianus | I6: 3
A7: Micropond | B7: Bullfrog | C7: 0 | D7: 45874 | E7: 0.125 | F7: 1 | G7: 12 | H7: Lithobates catesbeianus | I7: 3
A8: Micropond | B8: Bullfrog | C8: 0 | D8: 45874 | E8: 0.16666667 | F8: 0 | G8: 12 | H8: Lithobates catesbeianus | I8: 3
A9: Micropond | B9: Bullfrog | C9: 0 | D9: 45874 | E9: 0.20833333 | F9: 1 | G9: 12 | H9: Lithobates catesbeianus | I9: 3
A10: Micropond | B10: Bullfrog | C10: 0 | D10: 45874 | E10: 0.25 | F10: 0 | G10: 12 | H10: Lithobates catesbeianus | I10: 3
A11: Micropond | B11: Bullfrog | C11: 0 | D11: 45874 | E11: 0.29166667 | F11: 0 | G11: 12 | H11: Lithobates catesbeianus | I11: 3
A12: Micropond | B12: Bullfrog | C12: 0 | D12: 45874 | E12: 0.33333333 | F12: 0 | G12: 12 | H12: Lithobates catesbeianus | I12: 3
A13: Micropond | B13: Bullfrog | C13: 0 | D13: 45874 | E13: 0.375 | F13: 0 | G13: 12 | H13: Lithobates catesbeianus | I13: 3
... A581: Micro Pond | B581: Squirrel treefrog | C581: 0 | D581: 45877 | E581: 0.041666667 | F581: 1 | G581: 2 | H581: Hyla squirella | I581: 4

Sheet Sorted by time
A1: Site Name | B1: Species name | C1: Precipitation | D1: Date | E1: Time-Hour at which heard | F1: 5 Minute Block | G1: Total Minutes Called | H1: Scientific Name | I1: Different species calling at the same time
A2: Retention Pond | B2: Cope's Gray | C2: 0 | D2: 45814 | E2: 0 | F2: 1 | H2: Dryophytes chrysoscelis | I2: 3
A3: Retention Pond | B3: Cope's Gray | C3: 0 | D3: 45815 | E3: 0 | F3: 1 | H3: Dryophytes chrysoscelis | I3: 2
A4: Retention Pond | B4: Green treefrog | C4: 0 | D4: 45814 | E4: 0 | F4: 1 | H4: Hyla cinerea | I4: 3
A5: Retention Pond | B5: Squirrel treefrog | C5: 0 | D5: 45814 | E5: 0 | F5: 1 | H5: Hyla squirella | I5: 3
A6: Retention Pond | B6: Squirrel treefrog | C6: 0 | D6: 45815 | E6: 0 | F6: 1 | H6: Hyla squirella | I6: 2
A7: Micropond | B7: Bullfrog | D7: 45874 | E7: 0 | F7: 0 | H7: Lithobates catesbeianus
A8: Micropond | B8: Bullfrog | C8: 0 | D8: 45875 | E8: 0 | F8: 1 | H8: Lithobates catesbeianus | I8: 2
A9: Micropond | B9: Bullfrog | D9: 45876 | E9: 0 | F9: 0 | H9: Lithobates catesbeianus
A10: Micropond | B10: Bullfrog | D10: 45877 | E10: 0 | F10: 1 | H10: Lithobates catesbeianus
A11: Micropond | B11: Squirrel treefrog | C11: 0 | D11: 45877 | E11: 0 | F11: 1 | H11: Hyla squirella | I11: 3
A12: Micropond | B12: Green frog | C12: 0 | D12: 45872 | E12: 0 | F12: 1 | H12: Lithobates clamitans
A13: Micropond | B13: Green frog | C13: 0 | D13: 45873 | E13: 0 | F13: 1 | H13: Lithobates clamitans
A14: Micropond | B14: Green frog | C14: 0 | D14: 45874 | E14: 0 | F14: 1 | H14: Lithobates clamitans
A15: Micropond | B15: Green frog | C15: 0 | D15: 45875 | E15: 0 | F15: 1 | H15: Lithobates clamitans
A16: Micropond | B16: Green frog | C16: 0 | D16: 45877 | E16: 0 | F16: 1 | H16: Lithobates clamitans
A17: Micropond | B17: Cope's Gray | D17: 45877 | E17: 0 | F17: 1 | H17: Dryophytes chrysoscelis
A18: Retention Pond | B18: Cope's Gray | C18: 0 | E18: 0.00069444444 | F18: 0 | I18: 1
A19: Retention Pond | B19: Green treefrog | C19: 0 | E19: 0.00069444444 | F19: 0 | I19: 3
A20: Retention Pond | B20: Squirrel treefrog | C20: 0 | E20: 0.00069444444 | F20: 0 | I20: 3
A21: Retention Pond | B21: Squirrel treefrog | C21: 0 | E21: 0.00069444444 | F21: 0 | I21: 2
A22: Micropond | B22: Green frog | C22: 0 | D22: 45871 | E22: 0.00069444444 | F22: 1 | H22: Lithobates clamitans
A23: Micropond | B23: Green frog | C23: 0 | E23: 0.00069444444 | F23: 0
A24: Micropond | B24: Green frog | C24: 0 | E24: 0.00069444444 | F24: 0
A25: Micropond | B25: Green frog | C25: 0 | E25: 0.00069444444 | F25: 0
A26: Micropond | B26: Green frog | C26: 0 | E26: 0.00069444444 | F26: 0
A27: Micropond | B27: Cope's Gray | E27: 0.00069444444 | F27: 0
A28: Retention Pond | B28: Cope's Gray | C28: 0 | E28: 0.0013888889 | F28: 0 | I28: 3
A29: Retention Pond | B29: Green treefrog | C29: 0 | E29: 0.0013888889 | F29: 0 | I29: 3
A30: Retention Pond | B30: Green treefrog | C30: 0 | D30: 45815 | E30: 0.0013888889 | F30: 1 | H30: Hyla cinerea | I30: 3
A31: Retention Pond | B31: Squirrel treefrog | C31: 0 | E31: 0.0013888889 | F31: 0 | I31: 3
A32: Retention Pond | B32: Squirrel treefrog | C32: 0 | E32: 0.0013888889 | F32: 0 | I32: 3
A33: Micropond | B33: Bullfrog | C33: 0 | E33: 0.0013888889 | F33: 1
A34: Micropond | B34: Green frog | C34: 0 | E34: 0.0013888889 | F34: 0
A35: Micropond | B35: Green frog | C35: 0 | E35: 0.0013888889 | F35: 0
A36: Micropond | B36: Green frog | C36: 0 | E36: 0.0013888889 | F36: 0
A37: Micropond | B37: Green frog | C37: 0 | E37: 0.0013888889 | F37: 0
A38: Micropond | B38: Green frog | C38: 0 | E38: 0.0013888889 | F38: 0
A39: Micropond | B39: Green frog | C39: 0 | E39: 0.0013888889 | F39: 0
A40: Micropond | B40: Cope's Gray | E40: 0.0013888889 | F40: 0
...

Sheet Meredith
A1: Hypotheses: | B1: How many species of anurans can we audio record and match to visual species known?
B2: How many days that we record do we hear frogs? and which species?
B3: How many species are calling at once?
B4: How many hours of recording? | D4: How many hours with anuran calls?
B5: When during the day are they calling?
A6: Future hypotheses?
B7: Cue rates of different amphibian species-seasonality, temperature, location, and Bd loads
A9: Site Name | B9: Site Location | C9: Date | D9: Precipitation | E9: Temp Low and High in Farenheit | F9: Time 5 Minute Block | G9: Full Time of 5 Minutes | H9: Species | I9: Scientific Name | J9: Different species calling at the same time | K9: Total Number of times/Day
A10: Meredith College | B10: Retention Pond | C10: 45813 | D10: No | E10: 77/90 | F10: 0.5 | G10: No | H10: Squirrel tree frog | I10: Hyla squirella | J10: 1
A11: Meredith College | B11: Retention Pond | C11: 45813 | D11: No | E11: 77/90 | F11: 0.54166667 | G11: No | H11: Squirrel tree frog | I11: Hyla squirella | J11: 1
A12: Meredith College | B12: Retention Pond | C12: 45813 | D12: No | E12: 77/90 | F12: 0.54166667 | G12: No | H12: Squirrel tree frog | I12: Hyla squirella | J12: 2 | K12: 2
A13: Meredith College | B13: Retention Pond | C13: 45813 | D13: No | E13: 77/90 | F13: 0.54166667 | G13: No | H13: Cope's Gray | I13: Dryophytes chrysoscelis | J13: 2
A14: Meredith College | B14: Retention Pond | C14: 45813 | D14: No | E14: 77/90 | F14: 0.54166667 | G14: No | H14: Cope's Gray | I14: Dryophytes chrysoscelis | J14: 1 | K14: 1
A15: Meredith College | B15: Retention Pond | C15: 45814 | D15: No | E15: 72/91 | F15: 0 | G15: Yes | H15: Cope's Gray | I15: Dryophytes chrysoscelis | J15: 3 | K15: 9
A16: Meredith College | B16: Retention Pond | C16: 45814 | D16: No | E16: 72/91 | F16: 0 | G16: Yes | H16: Squirrel tree frog | I16: Hyla squirella | J16: 3 | K16: 7
A17: Meredith College | B17: Retention Pond | C17: 45814 | D17: No | E17: 72/91 | F17: 0 | G17: Yes | H17: Green tree frog | I17: Hyla cinerea | J17: 3 | K17: 8
A18: Meredith College | B18: Retention Pond | C18: 45814 | D18: No | E18: 72/91 | F18: 0.041666667 | G18: Yes | H18: Cope's Gray | I18: Dryophytes chrysoscelis | J18: 1
A19: Meredith College | B19: Retention Pond | C19: 45814 | D19: No | E19: 72/91 | F19: 0.043055556 | G19: No | H19: Squirrel tree frog | I19: Hyla squirella | J19: 3
A20: Meredith College | B20: Retention Pond | C20: 45814 | D20: No | E20: 72/91 | F20: 0.043055556 | G20: No | H20: Green tree frog | I20: Hyla cinerea | J20: 3
A21: Meredith College | B21: Retention Pond | C21: 45814 | D21: No | E21: 72/91 | F21: 0.04375 | G21: No | H21: Squirrel tree frog | I21: Hyla squirella | J21: 2
A22: Meredith College | B22: Retention Pond | C22: 45814 | D22: No | E22: 72/91 | F22: 0.083333333 | G22: Yes | H22: Cope's Gray | I22: Dryophytes chrysoscelis | J22: 1
A23: Meredith College | B23: Retention Pond | C23: 45814 | D23: No | E23: 72/91 | F23: 0.125 | G23: Yes | H23: Cope's Gray | I23: Dryophytes chrysoscelis | J23: 1
A24: Meredith College | B24: Retention Pond | C24: 45814 | D24: No | E24: 72/91 | F24: 0.12638889 | G24: No | H24: Bullfrog | I24: Lithobates catesbeianus | J24: 2 | K24: 1
A25: Meredith College | B25: Retention Pond | C25: 45814 | D25: No | E25: 72/91 | F25: 0.12708333 | G25: No | H25: Bullfrog | I25: Lithobates catesbeianus | J25: 3
A26: Meredith College | B26: Retention Pond | C26: 45814 | D26: No | E26: 72/91 | F26: 0.12708333 | G26: No | H26: Green Frog | I26: Lithobates clamitans | J26: 3 | K26: 2
A27: Meredith College | B27: Retention Pond | C27: 45814 | D27: No | E27: 72/91 | F27: 0.12777778 | G27: No | H27: Green tree frog | I27: Hyla cinerea | J27: 2
A28: Meredith College | B28: Retention Pond | C28: 45814 | D28: No | E28: 72/91 | F28: 0.16805556 | G28: No | H28: Cope's Gray | I28: Dryophytes chrysoscelis | J28: 1
A29: Meredith College | B29: Retention Pond | C29: 45814 | D29: No | E29: 72/91 | F29: 0.16875 | G29: No | H29: Cope's Gray | I29: Dryophytes chrysoscelis | J29: 2
A30: Meredith College | B30: Retention Pond | C30: 45814 | D30: No | E30: 72/91 | F30: 0.16875 | G30: No | H30: Green tree frog | I30: Hyla cinerea | J30: 2
A31: Meredith College | B31: Retention Pond | C31: 45814 | D31: No | E31: 72/91 | F31: 0.16944444 | G31: No | H31: Green tree frog | I31: Hyla cinerea | J31: 3
A32: Meredith College | B32: Retention Pond | C32: 45814 | D32: No | E32: 72/91 | F32: 0.16944444 | G32: No | H32: Cope's Gray | I32: Dryophytes chrysoscelis | J32: 3
A33: Meredith College | B33: Retention Pond | C33: 45814 | D33: No | E33: 72/91 | F33: 0.16944444 | G33: No | H33: Green Frog | I33: Lithobates clamitans | J33: 3
A34: Meredith College | B34: Retention Pond | C34: 45814 | D34: No | E34: 72/91 | F34: 0.20972222 | G34: No | H34: Cope's Gray | I34: Dryophytes chrysoscelis | J34: 3
A35: Meredith College | B35: Retention Pond | C35: 45814 | D35: No | E35: 72/91 | F35: 0.20972222 | G35: No | H35: Squirrel tree frog | I35: Hyla squirella | J35: 3
A36: Meredith College | B36: Retention Pond | C36: 45814 | D36: No | E36: 72/91 | F36: 0.20972222 | G36: No | H36: Green tree frog | I36: Hyla cinerea | J36: 3
A37: Meredith College | B37: Retention Pond | C37: 45814 | D37: No | E37: 72/91 | F37: 0.21041667 | G37: No | H37: Cope's Gray | I37: Dryophytes chrysoscelis | J37: 3
A38: Meredith College | B38: Retention Pond | C38: 45814 | D38: No | E38: 72/91 | F38: 0.21041667 | G38: No | H38: Squirrel tree frog | I38: Hyla squirella | J38: 3
... A56: Meredith College | B56: Retention Pond | C56: 45814 | D56: No | E56: 72/91 | F56: 0.95833333 | G56: Yes | H56: Green tree frog | I56: Hyla cinerea | J56: 3
A57: Meredith College | B57: Retention Pond | C57: 45815 | D57: No | E57: 71/91 | F57: 0 | G57: Yes | H57: Cope's Gray | I57: Dryophytes chrysoscelis | J57: 2 | K57: 4
A58: Meredith College | B58: Retention Pond | C58: 45815 | D58: No | E58: 71/91 | F58: 0 | G58: Yes | H58: Squirrel tree frog | I58: Hyla squirella | J58: 2 | K58: 3
...

Sheet Compiled Data
A1: Retention Pond:
A2: Species | B2: Scientific | D2: Total minutes | E2: Number of Days
A3: Squirrel treefrog | B3: Hyla squirella | D3: =SUM('Recompiled Data'!G83,'Recompiled Data'!G112,'Recompiled Data'!G125) -> 42 | E3: 3
A4: Green treefrog | B4: Hyla cinerea | D4: =SUM('Recompiled Data'!G67,'Recompiled Data'!G73) -> 30 | E4: 2
A5: Cope's Gray treefrog | B5: Dryophytes chrysoscelis | D5: =SUM('Recompiled Data'!G3,'Recompiled Data'!G29,'Recompiled Data'!G41) -> 37 | E5: 3
A6: Bullfrog | B6: Lithobates catesbeianus | D6: 1 | E6: 1
A7: Green frog | B7: Lithobates clamitans | D7: =SUM('Recompiled Data'!G76,'Recompiled Data'!G80) -> 5 | E7: 2
A9: Micro Pond:
A10: Species | B10: Scientific | D10: Total minutes | E10: Number of Days
A11: Squirrel treefrog | B11: Hyla squirella | D11: =SUM('Recompiled Data'!G237,'Recompiled Data'!G243,'Recompiled Data'!G246,'Recompiled Data'!G250) -> 14 | E11: 4
A12: Green treefrog | B12: Hyla cinerea | D12: =SUM('Recompiled Data'!G580,'Recompiled Data'!G582,'Recompiled Data'!G584,'Recompiled Data'!G586) -> 5 | E12: 4
A13: Cope's Gray treefrog | B13: Dryophytes chrysoscelis | D13: =SUM('Recompiled Data'!G590,'Recompiled Data'!G596,'Recompiled Data'!G604,'Recompiled Data'!G615) -> 25 | E13: 4
A14: Bullfrog | B14: Lithobates catesbeianus | D14: =SUM('Recompiled Data'!G153,'Recompiled Data'!G179,'Recompiled Data'!G205,'Recompiled Data'!G232) -> 103 | E14: 4
A15: Green frog | B15: Lithobates clamitans | D15: =SUM('Recompiled Data'!G255,'Recompiled Data'!G300,'Recompiled Data'!G354,'Recompiled Data'!G425,'Recompiled Data'!G479,'Recompiled Data'!G530,'Recompiled Data'!G544,'Recompiled Data'!G577) -> 319 | E15: 8

Sheet Anuran Species List
A1: Visual
A2: Species Name | B2: Scientific | E2: 46289.043
A3: Green tree frog | B3: Hyla cinerea | E3: 2:04:00 AM like half way | G3: high pitch
A4: Cope's Gray tf | B4: Dryophytes chrysosscelis | E4: 3 AM almost the end but not quite | G4: Alarmed squeal and jump into water
A5: Green/Bronze frog | B5: Lithobates clamitans | E5: 3:04 sounds like frogs but farther away? and another yelp towards end
A6: American Bullfrog | B6: Lithobates catesbaina
A8: Acoustic
A9: Species Name | B9: Scientific
A10: Green tree frog | B10: Hyla cinerea
A11: Cope's Gray tf | B11: Dryophytes chrysosscelis
A12: Green/Bronze frog | B12: Lithobates clamitans
A13: American Bullfrog | B13: Lithobates catesbaina
A14: Hyla squirella | B14: Hyla squirella

Sheet Graphs Anuran Species List
A1: Visual
A2: Species Name | B2: Scientific | D2: Visual Identification | E2: Audio Identification | I2: Visual
A3: Green tree frog | B3: Hyla cinerea | D3: X | E3: X | I3: Species Name | J3: Scientific
A4: Cope's Gray tf | B4: Dryophytes chrysosscelis | D4: X | E4: X | I4: Green treefrog | J4: Hyla cinerea
A5: Green/Bronze frog | B5: Lithobates clamitans | D5: X | E5: X | I5: Cope's Gray treefrog | J5: Dryophytes chrysosscelis
A6: American Bullfrog | B6: Lithobates catesbaina | D6: X | E6: X | I6: Green/Bronze frog | J6: Lithobates clamitans
A7: Squirrel tree frog | B7: Hyla squirella | E7: X | I7: American Bullfrog | J7: Lithobates catesbaina
I9: Acoustic
I10: Species Name | J10: Scientific
A11: Acoustic | I11: Green treefrog | J11: Hyla cinerea
A12: Species Name | B12: Scientific | D12: Visual Identification | E12: Audio Identification | F12: Species Name | I12: Cope's Gray treefrog | J12: Dryophytes chrysosscelis
A13: Hyla cinerea | D13: 25 | E13: 20 | F13: Hyla cinerea | I13: Green/Bronze frog | J13: Lithobates clamitans
A14: Dryophytes chrysoscelis | D14: 25 | E14: 20 | F14: Dryophytes chrysoscelis | I14: American Bullfrog | J14: Lithobates catesbaina
A15: Lithobates clamitans | D15: 25 | E15: 20 | F15: Lithobates clamitans | I15: Squirrel tree frog | J15: Hyla squirella
A16: Lithobates catesbeianus | D16: 25 | E16: 20 | F16: Lithobates catesbeianus
A17: Hyla squirella | B17: Hyla squirella | D17: 0 | E17: 20 | F17: Hyla squirella
A65: Visual Identification | B65: 4
A66: Audio Identification | B66: 5

Sheet Graphs Fall 2025
A1: Minutes called | I1: Times of day Retention | O1: Times of day Micropond
B2: Squirrel treefrog | C2: Green treefrog | D2: Cope's Gray treefrog | E2: Bullfrog | F2: Green frog | J2: Cope's Gray treefrog | K2: Green treefrog | L2: Squirrel treefrog | M2: Bullfrog | N2: Green frog | P2: Cope's Gray treefrog | Q2: Green treefrog | R2: Squirrel treefrog | S2: Bullfrog | T2: Green frog
A3: Retention pond - reedy marshy | B3: 42 | C3: 30 | D3: 37 | E3: 1 | F3: 5 | I3: 0 | J3: 1 | K3: 1 | L3: 1 | M3: 0 | N3: 0 | O3: 0 | P3: 1 | Q3: 1 | R3: 1 | S3: 1 | T3: 1
A4: Micropond - small pond | B4: 14 | C4: 5 | D4: 25 | E4: 103 | F4: 319 | I4: 0.041666667 | J4: 1 | K4: 1 | L4: 1 | M4: 0 | N4: 0 | O4: 0.041666667 | P4: 1 | Q4: 0 | R4: 1 | S4: 1 | T4: 1
I5: 0.083333333 | J5: 1 | K5: 0 | L5: 1 | M5: 0 | N5: 0 | O5: 0.083333333 | P5: 1 | Q5: 1 | R5: 0 | S5: 1 | T5: 1
I6: 0.125 | J6: 1 | K6: 1 | L6: 0 | M6: 0 | N6: 1 | O6: 0.125 | P6: 0 | Q6: 1 | R6: 0 | S6: 1 | T6: 1
I7: 0.16666667 | J7: 1 | K7: 1 | L7: 0 | M7: 0 | N7: 1 | O7: 0.16666667 | P7: 0 | Q7: 0 | R7: 0 | S7: 1 | T7: 1
I8: 0.20833333 | J8: 1 | K8: 1 | L8: 1 | M8: 0 | N8: 0 | O8: 0.20833333 | P8: 1 | Q8: 0 | R8: 1 | S8: 1 | T8: 1
I9: 0.25 | J9: 0 | K9: 0 | L9: 0 | M9: 0 | N9: 0 | O9: 0.25 | P9: 0 | Q9: 1 | R9: 1 | S9: 1 | T9: 1
I10: 0.29166667 | J10: 0 | K10: 0 | L10: 0 | M10: 0 | N10: 0 | O10: 0.29166667 | P10: 0 | Q10: 0 | R10: 0 | S10: 1 | T10: 1
I11: 0.33333333 | J11: 0 | K11: 0 | L11: 0 | M11: 0 | N11: 0 | O11: 0.33333333 | P11: 0 | Q11: 0 | R11: 0 | S11: 1 | T11: 1
I12: 0.375 | J12: 0 | K12: 0 | L12: 0 | M12: 0 | N12: 0 | O12: 0.375 | P12: 0 | Q12: 0 | R12: 0 | S12: 1 | T12: 1
I13: 0.41666667 | J13: 0 | K13: 1 | L13: 0 | M13: 0 | N13: 0 | O13: 0.41666667 | P13: 0 | Q13: 0 | R13: 0 | S13: 1 | T13: 1
I14: 0.45833333 | J14: 0 | K14: 0 | L14: 0 | M14: 0 | N14: 0 | O14: 0.45833333 | P14: 0 | Q14: 0 | R14: 0 | S14: 1 | T14: 1
I15: 0.5 | J15: 0 | K15: 0 | L15: 1 | M15: 0 | N15: 0 | O15: 0.5 | P15: 0 | Q15: 0 | R15: 0 | S15: 1 | T15: 1
I16: 0.54166667 | J16: 1 | K16: 0 | L16: 1 | M16: 0 | N16: 0 | O16: 0.54166667 | P16: 0 | Q16: 0 | R16: 0 | S16: 1 | T16: 1
... I26: 0.95833333 | J26: 1 | K26: 1 | L26: 1 | M26: 0 | N26: 0 | O26: 0.95833333 | P26: 0 | Q26: 0 | R26: 1 | S26: 1 | T26: 1

Sheet Spring 2026
A1: Times of day Retention | G1: Times of day Micropond
B2: Cope's Gray treefrog | C2: Green treefrog | D2: Squirrel treefrog | E2: Bullfrog | F2: Green frog | H2: Cope's Gray treefrog | I2: Green treefrog | J2: Squirrel treefrog | K2: Bullfrog | L2: Green frog
A3: 0 | B3: 1 | C3: 1 | D3: 1 | E3: 0 | F3: 0 | G3: 0 | H3: 1 | I3: 1 | J3: 1 | K3: 1 | L3: 1
A4: 0.041666667 | B4: 1 | C4: 1 | D4: 1 | E4: 0 | F4: 0 | G4: 0.041666667 | H4: 1 | I4: 0 | J4: 1 | K4: 1 | L4: 1
A5: 0.083333333 | B5: 1 | C5: 0 | D5: 1 | E5: 0 | F5: 0 | G5: 0.083333333 | H5: 1 | I5: 1 | J5: 0 | K5: 1 | L5: 1
A6: 0.125 | B6: 1 | C6: 1 | D6: 0 | E6: 0 | F6: 1 | G6: 0.125 | H6: 0 | I6: 1 | J6: 0 | K6: 1 | L6: 1
A7: 0.16666667 | B7: 1 | C7: 1 | D7: 0 | E7: 0 | F7: 1 | G7: 0.16666667 | H7: 0 | I7: 0 | J7: 0 | K7: 1 | L7: 1
A8: 0.20833333 | B8: 1 | C8: 1 | D8: 1 | E8: 0 | F8: 0 | G8: 0.20833333 | H8: 1 | I8: 0 | J8: 1 | K8: 1 | L8: 1
A9: 0.25 | B9: 0 | C9: 0 | D9: 0 | E9: 0 | F9: 0 | G9: 0.25 | H9: 0 | I9: 1 | J9: 1 | K9: 1 | L9: 1
A10: 0.29166667 | B10: 0 | C10: 0 | D10: 0 | E10: 0 | F10: 0 | G10: 0.29166667 | H10: 0 | I10: 0 | J10: 0 | K10: 1 | L10: 1
A11: 0.33333333 | B11: 0 | C11: 0 | D11: 0 | E11: 0 | F11: 0 | G11: 0.33333333 | H11: 0 | I11: 0 | J11: 0 | K11: 1 | L11: 1
A12: 0.375 | B12: 0 | C12: 0 | D12: 0 | E12: 0 | F12: 0 | G12: 0.375 | H12: 0 | I12: 0 | J12: 0 | K12: 1 | L12: 1
A13: 0.41666667 | B13: 0 | C13: 1 | D13: 0 | E13: 0 | F13: 0 | G13: 0.41666667 | H13: 0 | I13: 0 | J13: 0 | K13: 1 | L13: 1
A14: 0.45833333 | B14: 0 | C14: 0 | D14: 0 | E14: 0 | F14: 0 | G14: 0.45833333 | H14: 0 | I14: 0 | J14: 0 | K14: 1 | L14: 1
... A26: 0.95833333 | B26: 1 | C26: 1 | D26: 1 | E26: 0 | F26: 0 | G26: 0.95833333 | H26: 0 | I26: 0 | J26: 1 | K26: 1 | L26: 1
A30: Times of day Retention
A32: Cope's Gray treefrog | B32: 1 | C32: 1 | D32: 1 | E32: 1 | F32: 1 | G32: 1 | O32: 1 | W32: 1 | X32: 1 | Y32: 1
A33: Green treefrog | B33: 1 | C33: 1 | E33: 1 | F33: 1 | G33: 1 | L33: 1 | W33: 1 | X33: 1 | Y33: 1
A34: Squirrel treefrog | B34: 1 | C34: 1 | D34: 1 | G34: 1 | N34: 1 | O34: 1 | V34: 1 | W34: 1 | X34: 1 | Y34: 1
A35: Bullfrog
A36: Green frog | E36: 1 | F36: 1
B37: 0 | C37: 0.041666667 | D37: 0.083333333 | E37: 0.125 | F37: 0.16666667 | G37: 0.20833333 | H37: 0.25 | I37: 0.29166667 | J37: 0.33333333 | K37: 0.375 | L37: 0.41666667 | M37: 0.45833333 | N37: 0.5 | O37: 0.54166667 | P37: 0.58333333 | Q37: 0.625 | R37: 0.66666667 | S37: 0.70833333 | T37: 0.75 | U37: 0.79166667 | V37: 0.83333333 | W37: 0.875 | X37: 0.91666667 | Y37: 0.95833333
